test/unit/add_cancel/state.json
[
	{
		"bids": [
			{
				"price": 1023000000,
				"size": 5234591011,
				"order_id": 0,
				"user_id": 2
			}
		],
		"asks": [],
		"state_num": 2,
		"output_seq": 3,
		"ticker": {},
		"recovery_journal": "matcher_in.0.1317086239.log"
	},
	{
		"bids": [
			{
				"price": 1024000000,
				"size": 1023400000,
				"order_id": 1,
				"user_id": 2
			},
			{
				"price": 1023000000,
				"size": 5234591011,
				"order_id": 0,
				"user_id": 2
			}
		],
		"asks": [],
		"state_num": 2,
		"output_seq": 5,
		"ticker": {},
		"recovery_journal": "matcher_in.0.1317086239.log"
	},
	{
		"bids": [
			{
				"price": 1024000000,
				"size": 1023400000,
				"order_id": 1,
				"user_id": 2
			},
			{
				"price": 1023000000,
				"size": 5234591011,
				"order_id": 0,
				"user_id": 2
			},
			{
				"price": 1023000000,
				"size": 1020000000,
				"order_id": 2,
				"user_id": 2
			}
		],
		"asks": [],
		"state_num": 2,
		"output_seq": 7,
		"ticker": {},
		"recovery_journal": "matcher_in.0.1317086239.log"
	},
	{
		"bids": [
			{
				"price": 1024000000,
				"size": 1023400000,
				"order_id": 1,
				"user_id": 2
			},
			{
				"price": 1023000000,
				"size": 1020000000,
				"order_id": 2,
				"user_id": 2
			}
		],
		"asks": [],
		"state_num": 2,
		"output_seq": 8,
		"ticker": {},
		"recovery_journal": "matcher_in.0.1317086239.log"
	},
	{
		"bids": [
			{
				"price": 1024000000,
				"size": 1023400000,
				"order_id": 1,
				"user_id": 2
			},
			{
				"price": 1023000000,
				"size": 1020000000,
				"order_id": 2,
				"user_id": 2
			}
		],
		"asks": [
			{
				"price": 1800000000,
				"size": 8056912305,
				"order_id": 5,
				"user_id": 2
			}
		],
		"state_num": 2,
		"output_seq": 10,
		"ticker": {},
		"recovery_journal": "matcher_in.0.1317086239.log"
	},
	{
		"bids": [
			{
				"price": 1024000000,
				"size": 1023400000,
				"order_id": 1,
				"user_id": 2
			},
			{
				"price": 1023000000,
				"size": 1020000000,
				"order_id": 2,
				"user_id": 2
			}
		],
		"asks": [
			{
				"price": 1100000000,
				"size": 120000000,
				"order_id": 3,
				"user_id": 2
			},
			{
				"price": 1800000000,
				"size": 8056912305,
				"order_id": 5,
				"user_id": 2
			}
		],
		"state_num": 2,
		"output_seq": 12,
		"ticker": {},
		"recovery_journal": "matcher_in.0.1317086239.log"
	},
	{
		"bids": [
			{
				"price": 1024000000,
				"size": 1023400000,
				"order_id": 1,
				"user_id": 2
			},
			{
				"price": 1023000000,
				"size": 1020000000,
				"order_id": 2,
				"user_id": 2
			}
		],
		"asks": [
			{
				"price": 1100000000,
				"size": 120000000,
				"order_id": 3,
				"user_id": 2
			},
			{
				"price": 1100000000,
				"size": 210000000,
				"order_id": 4,
				"user_id": 2
			},
			{
				"price": 1800000000,
				"size": 8056912305,
				"order_id": 5,
				"user_id": 2
			}
		],
		"state_num": 2,
		"output_seq": 14,
		"ticker": {},
		"recovery_journal": "matcher_in.0.1317086239.log"
	},
	{
		"bids": [
			{
				"price": 1024000000,
				"size": 1023400000,
				"order_id": 1,
				"user_id": 2
			}
		],
		"asks": [
			{
				"price": 1100000000,
				"size": 120000000,
				"order_id": 3,
				"user_id": 2
			},
			{
				"price": 1100000000,
				"size": 210000000,
				"order_id": 4,
				"user_id": 2
			},
			{
				"price": 1800000000,
				"size": 8056912305,
				"order_id": 5,
				"user_id": 2
			}
		],
		"state_num": 2,
		"output_seq": 15,
		"ticker": {},
		"recovery_journal": "matcher_in.0.1317086239.log"
	},
	{
		"bids": [
			{
				"price": 1024000000,
				"size": 1023400000,
				"order_id": 1,
				"user_id": 2
			}
		],
		"asks": [
			{
				"price": 1100000000,
				"size": 120000000,
				"order_id": 3,
				"user_id": 2
			},
			{
				"price": 1100000000,
				"size": 210000000,
				"order_id": 4,
				"user_id": 2
			},
			{
				"price": 1800000000,
				"size": 8056912305,
				"order_id": 5,
				"user_id": 2
			}
		],
		"state_num": 2,
		"output_seq": 15,
		"ticker": {},
		"recovery_journal": "matcher_in.0.1317086239.log"
	}
]
