test/unit/add_fill_cancel/state.json
[
	{
		"bids": [
			{
				"price": 1023000000,
				"size": 5234591011,
				"order_id": 0,
				"user_id": 2
			}
		],
		"asks": [],
		"state_num": 2,
		"output_seq": 3,
		"ticker": {},
		"recovery_journal": "matcher_in.0.1317086239.log"
	},
	{
		"bids": [
			{
				"price": 1023000000,
				"size": 4211191011,
				"order_id": 0,
				"user_id": 2
			}
		],
		"asks": [],
		"state_num": 2,
		"output_seq": 6,
		"ticker": {
			"price": 1023000000,
			"size": 1023400000,
			"timestamp": 1317086239.693123
		},
		"recovery_journal": "matcher_in.0.1317086239.log"
	},
	{
		"bids": [
			{
				"price": 1023000000,
				"size": 4211191011,
				"order_id": 0,
				"user_id": 2
			}
		],
		"asks": [],
		"state_num": 2,
		"output_seq": 6,
		"ticker": {
			"price": 1023000000,
			"size": 1023400000,
			"timestamp": 1317086239.693123
		},
		"recovery_journal": "matcher_in.0.1317086239.log"
	},
	{
		"bids": [],
		"asks": [],
		"state_num": 2,
		"output_seq": 7,
		"ticker": {
			"price": 1023000000,
			"size": 1023400000,
			"timestamp": 1317086239.693123
		},
		"recovery_journal": "matcher_in.0.1317086239.log"
	},
	{
		"bids": [
			{
				"price": 220000000,
				"size": 1010000000,
				"order_id": 3,
				"user_id": 3
			}
		],
		"asks": [],
		"state_num": 2,
		"output_seq": 9,
		"ticker": {
			"price": 1023000000,
			"size": 1023400000,
			"timestamp": 1317086239.693123
		},
		"recovery_journal": "matcher_in.0.1317086239.log"
	},
	{
		"bids": [],
		"asks": [],
		"state_num": 2,
		"output_seq": 13,
		"ticker": {
			"price": 220000000,
			"size": 1010000000,
			"timestamp": 1317086239.693123
		},
		"recovery_journal": "matcher_in.0.1317086239.log"
	},
	{
		"bids": [],
		"asks": [],
		"state_num": 2,
		"output_seq": 13,
		"ticker": {
			"price": 220000000,
			"size": 1010000000,
			"timestamp": 1317086239.693123
		},
		"recovery_journal": "matcher_in.0.1317086239.log"
	},
	{
		"bids": [],
		"asks": [],
		"state_num": 2,
		"output_seq": 13,
		"ticker": {
			"price": 220000000,
			"size": 1010000000,
			"timestamp": 1317086239.693123
		},
		"recovery_journal": "matcher_in.0.1317086239.log"
	}
]
