test/unit/match_full/state.json
[
	{
		"bids": [
			{
				"price": 1023000000,
				"size": 5234591011,
				"order_id": 0,
				"user_id": 2
			}
		],
		"asks": [],
		"state_num": 2,
		"output_seq": 2,
		"ticker": {
			"price": 220000000,
			"size": 1010000000,
			"timestamp": 1317086239.693123
		}
	},
	{
		"bids": [
			{
				"price": 1024000000,
				"size": 1023400000,
				"order_id": 1,
				"user_id": 2
			},
			{
				"price": 1023000000,
				"size": 5234591011,
				"order_id": 0,
				"user_id": 2
			}
		],
		"asks": [],
		"state_num": 2,
		"output_seq": 4,
		"ticker": {
			"price": 220000000,
			"size": 1010000000,
			"timestamp": 1317086239.693123
		}
	},
	{
		"bids": [
			{
				"price": 1024000000,
				"size": 1023400000,
				"order_id": 1,
				"user_id": 2
			},
			{
				"price": 1023000000,
				"size": 5234591011,
				"order_id": 0,
				"user_id": 2
			},
			{
				"price": 1023000000,
				"size": 1020000000,
				"order_id": 2,
				"user_id": 2
			}
		],
		"asks": [],
		"state_num": 2,
		"output_seq": 6,
		"ticker": {
			"price": 220000000,
			"size": 1010000000,
			"timestamp": 1317086239.693123
		}
	},
	{
		"bids": [
			{
				"price": 1024000000,
				"size": 1023400000,
				"order_id": 1,
				"user_id": 2
			},
			{
				"price": 1023000000,
				"size": 5234591011,
				"order_id": 0,
				"user_id": 2
			},
			{
				"price": 1023000000,
				"size": 1020000000,
				"order_id": 2,
				"user_id": 2
			}
		],
		"asks": [
			{
				"price": 1800000000,
				"size": 8056912305,
				"order_id": 5,
				"user_id": 3
			}
		],
		"state_num": 2,
		"output_seq": 8,
		"ticker": {
			"price": 220000000,
			"size": 1010000000,
			"timestamp": 1317086239.693123
		}
	},
	{
		"bids": [
			{
				"price": 1024000000,
				"size": 1023400000,
				"order_id": 1,
				"user_id": 2
			},
			{
				"price": 1023000000,
				"size": 5234591011,
				"order_id": 0,
				"user_id": 2
			},
			{
				"price": 1023000000,
				"size": 1020000000,
				"order_id": 2,
				"user_id": 2
			}
		],
		"asks": [
			{
				"price": 1100000000,
				"size": 120000000,
				"order_id": 3,
				"user_id": 3
			},
			{
				"price": 1800000000,
				"size": 8056912305,
				"order_id": 5,
				"user_id": 3
			}
		],
		"state_num": 2,
		"output_seq": 10,
		"ticker": {
			"price": 220000000,
			"size": 1010000000,
			"timestamp": 1317086239.693123
		}
	},
	{
		"bids": [
			{
				"price": 1024000000,
				"size": 1023400000,
				"order_id": 1,
				"user_id": 2
			},
			{
				"price": 1023000000,
				"size": 5234591011,
				"order_id": 0,
				"user_id": 2
			},
			{
				"price": 1023000000,
				"size": 1020000000,
				"order_id": 2,
				"user_id": 2
			}
		],
		"asks": [
			{
				"price": 1100000000,
				"size": 120000000,
				"order_id": 3,
				"user_id": 3
			},
			{
				"price": 1100000000,
				"size": 210000000,
				"order_id": 4,
				"user_id": 3
			},
			{
				"price": 1800000000,
				"size": 8056912305,
				"order_id": 5,
				"user_id": 3
			}
		],
		"state_num": 2,
		"output_seq": 12,
		"ticker": {
			"price": 220000000,
			"size": 1010000000,
			"timestamp": 1317086239.693123
		}
	},
	{
		"bids": [
			{
				"price": 1024000000,
				"size": 1023400000,
				"order_id": 1,
				"user_id": 2
			},
			{
				"price": 1023000000,
				"size": 5234591011,
				"order_id": 0,
				"user_id": 2
			},
			{
				"price": 1023000000,
				"size": 1020000000,
				"order_id": 2,
				"user_id": 2
			}
		],
		"asks": [
			{
				"price": 1100000000,
				"size": 210000000,
				"order_id": 4,
				"user_id": 3
			},
			{
				"price": 1800000000,
				"size": 8056912305,
				"order_id": 5,
				"user_id": 3
			}
		],
		"state_num": 2,
		"output_seq": 16,
		"ticker": {
			"price": 1100000000,
			"size": 120000000,
			"timestamp": 1317086239.693123
		}
	},
	{
		"bids": [
			{
				"price": 1023000000,
				"size": 5234591011,
				"order_id": 0,
				"user_id": 2
			},
			{
				"price": 1023000000,
				"size": 1020000000,
				"order_id": 2,
				"user_id": 2
			}
		],
		"asks": [
			{
				"price": 1100000000,
				"size": 210000000,
				"order_id": 4,
				"user_id": 3
			},
			{
				"price": 1800000000,
				"size": 8056912305,
				"order_id": 5,
				"user_id": 3
			}
		],
		"state_num": 2,
		"output_seq": 20,
		"ticker": {
			"price": 1024000000,
			"size": 1023400000,
			"timestamp": 1317086239.693123
		}
	},
	{
		"bids": [
			{
				"price": 1023000000,
				"size": 5234591011,
				"order_id": 0,
				"user_id": 2
			},
			{
				"price": 1023000000,
				"size": 1020000000,
				"order_id": 2,
				"user_id": 2
			}
		],
		"asks": [
			{
				"price": 1800000000,
				"size": 8056912305,
				"order_id": 5,
				"user_id": 3
			}
		],
		"state_num": 2,
		"output_seq": 24,
		"ticker": {
			"price": 1100000000,
			"size": 210000000,
			"timestamp": 1317086239.693123
		}
	}
]
