test/unit/match_over/state.json
[
	{
		"bids": [
			{
				"price": 1023000000,
				"size": 5234591011,
				"order_id": 0,
				"sender_id": "bc21105829fa4ddf981f6cd5366b5af7"
			}
		],
		"asks": [],
		"state_num": 2,
		"output_seq": 2
	},
	{
		"bids": [
			{
				"price": 1024000000,
				"size": 1023400000,
				"order_id": 1,
				"sender_id": "3b95ea087ddb475db5e98f7137640880"
			},
			{
				"price": 1023000000,
				"size": 5234591011,
				"order_id": 0,
				"sender_id": "bc21105829fa4ddf981f6cd5366b5af7"
			}
		],
		"asks": [],
		"state_num": 2,
		"output_seq": 4
	},
	{
		"bids": [
			{
				"price": 1024000000,
				"size": 1023400000,
				"order_id": 1,
				"sender_id": "3b95ea087ddb475db5e98f7137640880"
			},
			{
				"price": 1023000000,
				"size": 5234591011,
				"order_id": 0,
				"sender_id": "bc21105829fa4ddf981f6cd5366b5af7"
			},
			{
				"price": 1023000000,
				"size": 1020000000,
				"order_id": 2,
				"sender_id": "e035fc9fa1034a8eabfa4e50cb3cb303"
			}
		],
		"asks": [],
		"state_num": 2,
		"output_seq": 6
	},
	{
		"bids": [
			{
				"price": 1024000000,
				"size": 1023400000,
				"order_id": 1,
				"sender_id": "3b95ea087ddb475db5e98f7137640880"
			},
			{
				"price": 1023000000,
				"size": 5234591011,
				"order_id": 0,
				"sender_id": "bc21105829fa4ddf981f6cd5366b5af7"
			},
			{
				"price": 1023000000,
				"size": 1020000000,
				"order_id": 2,
				"sender_id": "e035fc9fa1034a8eabfa4e50cb3cb303"
			}
		],
		"asks": [
			{
				"price": 1800000000,
				"size": 8056912305,
				"order_id": 5,
				"sender_id": "9c517fcc473f47a494b4b5aea366477a"
			}
		],
		"state_num": 2,
		"output_seq": 8
	},
	{
		"bids": [
			{
				"price": 1024000000,
				"size": 1023400000,
				"order_id": 1,
				"sender_id": "3b95ea087ddb475db5e98f7137640880"
			},
			{
				"price": 1023000000,
				"size": 5234591011,
				"order_id": 0,
				"sender_id": "bc21105829fa4ddf981f6cd5366b5af7"
			},
			{
				"price": 1023000000,
				"size": 1020000000,
				"order_id": 2,
				"sender_id": "e035fc9fa1034a8eabfa4e50cb3cb303"
			}
		],
		"asks": [
			{
				"price": 1100000000,
				"size": 120000000,
				"order_id": 3,
				"sender_id": "f707b4ead3004fa09e80a7924822c311"
			},
			{
				"price": 1800000000,
				"size": 8056912305,
				"order_id": 5,
				"sender_id": "9c517fcc473f47a494b4b5aea366477a"
			}
		],
		"state_num": 2,
		"output_seq": 10
	},
	{
		"bids": [
			{
				"price": 1024000000,
				"size": 1023400000,
				"order_id": 1,
				"sender_id": "3b95ea087ddb475db5e98f7137640880"
			},
			{
				"price": 1023000000,
				"size": 5234591011,
				"order_id": 0,
				"sender_id": "bc21105829fa4ddf981f6cd5366b5af7"
			},
			{
				"price": 1023000000,
				"size": 1020000000,
				"order_id": 2,
				"sender_id": "e035fc9fa1034a8eabfa4e50cb3cb303"
			}
		],
		"asks": [
			{
				"price": 1100000000,
				"size": 120000000,
				"order_id": 3,
				"sender_id": "f707b4ead3004fa09e80a7924822c311"
			},
			{
				"price": 1100000000,
				"size": 210000000,
				"order_id": 4,
				"sender_id": "4adbfc1f0e6645789ee99da9cb54540e"
			},
			{
				"price": 1800000000,
				"size": 8056912305,
				"order_id": 5,
				"sender_id": "9c517fcc473f47a494b4b5aea366477a"
			}
		],
		"state_num": 2,
		"output_seq": 12
	},
	{
		"bids": [],
		"asks": [
			{
				"price": 1000000,
				"size": 2732008989,
				"order_id": 9,
				"sender_id": "7957f956edf744cca01927025547b011"
			},
			{
				"price": 1100000000,
				"size": 120000000,
				"order_id": 3,
				"sender_id": "f707b4ead3004fa09e80a7924822c311"
			},
			{
				"price": 1100000000,
				"size": 210000000,
				"order_id": 4,
				"sender_id": "4adbfc1f0e6645789ee99da9cb54540e"
			},
			{
				"price": 1800000000,
				"size": 8056912305,
				"order_id": 5,
				"sender_id": "9c517fcc473f47a494b4b5aea366477a"
			}
		],
		"state_num": 2,
		"output_seq": 20
	},
	{
		"bids": [
			{
				"price": 10000000000,
				"size": 8911078706,
				"order_id": 9,
				"sender_id": "6214bbd490e44594b64b5e4903e14302"
			}
		],
		"asks": [],
		"state_num": 2,
		"output_seq": 30
	}
]
