test/unit/match_partial/state.json
[
	{
		"bids": [
			{
				"price": 1023000000,
				"size": 5234591011,
				"order_id": 0,
				"sender_id": "b7211f8a704b4815be93c07dcb354e4d"
			}
		],
		"asks": [],
		"state_num": 2,
		"output_seq": 2
	},
	{
		"bids": [
			{
				"price": 1024000000,
				"size": 1023400000,
				"order_id": 1,
				"sender_id": "1fa34b0f04e249c2940a6fbb8bae105c"
			},
			{
				"price": 1023000000,
				"size": 5234591011,
				"order_id": 0,
				"sender_id": "b7211f8a704b4815be93c07dcb354e4d"
			}
		],
		"asks": [],
		"state_num": 2,
		"output_seq": 4
	},
	{
		"bids": [
			{
				"price": 1024000000,
				"size": 1023400000,
				"order_id": 1,
				"sender_id": "1fa34b0f04e249c2940a6fbb8bae105c"
			},
			{
				"price": 1023000000,
				"size": 5234591011,
				"order_id": 0,
				"sender_id": "b7211f8a704b4815be93c07dcb354e4d"
			},
			{
				"price": 1023000000,
				"size": 1020000000,
				"order_id": 2,
				"sender_id": "fd0d457e3a4e43fe85f84d8c0b95cdd2"
			}
		],
		"asks": [],
		"state_num": 2,
		"output_seq": 6
	},
	{
		"bids": [
			{
				"price": 1024000000,
				"size": 1023400000,
				"order_id": 1,
				"sender_id": "1fa34b0f04e249c2940a6fbb8bae105c"
			},
			{
				"price": 1023000000,
				"size": 5234591011,
				"order_id": 0,
				"sender_id": "b7211f8a704b4815be93c07dcb354e4d"
			},
			{
				"price": 1023000000,
				"size": 1020000000,
				"order_id": 2,
				"sender_id": "fd0d457e3a4e43fe85f84d8c0b95cdd2"
			}
		],
		"asks": [
			{
				"price": 1800000000,
				"size": 8056912305,
				"order_id": 5,
				"sender_id": "19a61efb542c4c4697d09769092bfab1"
			}
		],
		"state_num": 2,
		"output_seq": 8
	},
	{
		"bids": [
			{
				"price": 1024000000,
				"size": 1023400000,
				"order_id": 1,
				"sender_id": "1fa34b0f04e249c2940a6fbb8bae105c"
			},
			{
				"price": 1023000000,
				"size": 5234591011,
				"order_id": 0,
				"sender_id": "b7211f8a704b4815be93c07dcb354e4d"
			},
			{
				"price": 1023000000,
				"size": 1020000000,
				"order_id": 2,
				"sender_id": "fd0d457e3a4e43fe85f84d8c0b95cdd2"
			}
		],
		"asks": [
			{
				"price": 1100000000,
				"size": 120000000,
				"order_id": 3,
				"sender_id": "20a867503a244976ab894bbb54d1e76c"
			},
			{
				"price": 1800000000,
				"size": 8056912305,
				"order_id": 5,
				"sender_id": "19a61efb542c4c4697d09769092bfab1"
			}
		],
		"state_num": 2,
		"output_seq": 10
	},
	{
		"bids": [
			{
				"price": 1024000000,
				"size": 1023400000,
				"order_id": 1,
				"sender_id": "1fa34b0f04e249c2940a6fbb8bae105c"
			},
			{
				"price": 1023000000,
				"size": 5234591011,
				"order_id": 0,
				"sender_id": "b7211f8a704b4815be93c07dcb354e4d"
			},
			{
				"price": 1023000000,
				"size": 1020000000,
				"order_id": 2,
				"sender_id": "fd0d457e3a4e43fe85f84d8c0b95cdd2"
			}
		],
		"asks": [
			{
				"price": 1100000000,
				"size": 120000000,
				"order_id": 3,
				"sender_id": "20a867503a244976ab894bbb54d1e76c"
			},
			{
				"price": 1100000000,
				"size": 210000000,
				"order_id": 4,
				"sender_id": "dbaae29301c24070a8237468ee52af81"
			},
			{
				"price": 1800000000,
				"size": 8056912305,
				"order_id": 5,
				"sender_id": "19a61efb542c4c4697d09769092bfab1"
			}
		],
		"state_num": 2,
		"output_seq": 12
	},
	{
		"bids": [
			{
				"price": 1059000000,
				"size": 110000000,
				"order_id": 6,
				"sender_id": "e2f78b80dac5460db20700e42a136920"
			},
			{
				"price": 1024000000,
				"size": 1023400000,
				"order_id": 1,
				"sender_id": "1fa34b0f04e249c2940a6fbb8bae105c"
			},
			{
				"price": 1023000000,
				"size": 5234591011,
				"order_id": 0,
				"sender_id": "b7211f8a704b4815be93c07dcb354e4d"
			},
			{
				"price": 1023000000,
				"size": 1020000000,
				"order_id": 2,
				"sender_id": "fd0d457e3a4e43fe85f84d8c0b95cdd2"
			}
		],
		"asks": [
			{
				"price": 1100000000,
				"size": 120000000,
				"order_id": 3,
				"sender_id": "20a867503a244976ab894bbb54d1e76c"
			},
			{
				"price": 1100000000,
				"size": 210000000,
				"order_id": 4,
				"sender_id": "dbaae29301c24070a8237468ee52af81"
			},
			{
				"price": 1800000000,
				"size": 8056912305,
				"order_id": 5,
				"sender_id": "19a61efb542c4c4697d09769092bfab1"
			}
		],
		"state_num": 2,
		"output_seq": 14
	},
	{
		"bids": [
			{
				"price": 1059000000,
				"size": 110000000,
				"order_id": 6,
				"sender_id": "e2f78b80dac5460db20700e42a136920"
			},
			{
				"price": 1024000000,
				"size": 1023400000,
				"order_id": 1,
				"sender_id": "1fa34b0f04e249c2940a6fbb8bae105c"
			},
			{
				"price": 1023000000,
				"size": 5234591011,
				"order_id": 0,
				"sender_id": "b7211f8a704b4815be93c07dcb354e4d"
			},
			{
				"price": 1023000000,
				"size": 1020000000,
				"order_id": 2,
				"sender_id": "fd0d457e3a4e43fe85f84d8c0b95cdd2"
			}
		],
		"asks": [
			{
				"price": 1100000000,
				"size": 100000000,
				"order_id": 3,
				"sender_id": "20a867503a244976ab894bbb54d1e76c"
			},
			{
				"price": 1100000000,
				"size": 210000000,
				"order_id": 4,
				"sender_id": "dbaae29301c24070a8237468ee52af81"
			},
			{
				"price": 1800000000,
				"size": 8056912305,
				"order_id": 5,
				"sender_id": "19a61efb542c4c4697d09769092bfab1"
			}
		],
		"state_num": 2,
		"output_seq": 16
	},
	{
		"bids": [
			{
				"price": 1059000000,
				"size": 110000000,
				"order_id": 6,
				"sender_id": "e2f78b80dac5460db20700e42a136920"
			},
			{
				"price": 1024000000,
				"size": 1023400000,
				"order_id": 1,
				"sender_id": "1fa34b0f04e249c2940a6fbb8bae105c"
			},
			{
				"price": 1023000000,
				"size": 5234591011,
				"order_id": 0,
				"sender_id": "b7211f8a704b4815be93c07dcb354e4d"
			},
			{
				"price": 1023000000,
				"size": 1020000000,
				"order_id": 2,
				"sender_id": "fd0d457e3a4e43fe85f84d8c0b95cdd2"
			}
		],
		"asks": [
			{
				"price": 1100000000,
				"size": 80000000,
				"order_id": 3,
				"sender_id": "20a867503a244976ab894bbb54d1e76c"
			},
			{
				"price": 1100000000,
				"size": 210000000,
				"order_id": 4,
				"sender_id": "dbaae29301c24070a8237468ee52af81"
			},
			{
				"price": 1800000000,
				"size": 8056912305,
				"order_id": 5,
				"sender_id": "19a61efb542c4c4697d09769092bfab1"
			}
		],
		"state_num": 2,
		"output_seq": 18
	},
	{
		"bids": [
			{
				"price": 1059000000,
				"size": 90000000,
				"order_id": 6,
				"sender_id": "e2f78b80dac5460db20700e42a136920"
			},
			{
				"price": 1024000000,
				"size": 1023400000,
				"order_id": 1,
				"sender_id": "1fa34b0f04e249c2940a6fbb8bae105c"
			},
			{
				"price": 1023000000,
				"size": 5234591011,
				"order_id": 0,
				"sender_id": "b7211f8a704b4815be93c07dcb354e4d"
			},
			{
				"price": 1023000000,
				"size": 1020000000,
				"order_id": 2,
				"sender_id": "fd0d457e3a4e43fe85f84d8c0b95cdd2"
			}
		],
		"asks": [
			{
				"price": 1100000000,
				"size": 80000000,
				"order_id": 3,
				"sender_id": "20a867503a244976ab894bbb54d1e76c"
			},
			{
				"price": 1100000000,
				"size": 210000000,
				"order_id": 4,
				"sender_id": "dbaae29301c24070a8237468ee52af81"
			},
			{
				"price": 1800000000,
				"size": 8056912305,
				"order_id": 5,
				"sender_id": "19a61efb542c4c4697d09769092bfab1"
			}
		],
		"state_num": 2,
		"output_seq": 20
	},
	{
		"bids": [
			{
				"price": 1059000000,
				"size": 70000000,
				"order_id": 6,
				"sender_id": "e2f78b80dac5460db20700e42a136920"
			},
			{
				"price": 1024000000,
				"size": 1023400000,
				"order_id": 1,
				"sender_id": "1fa34b0f04e249c2940a6fbb8bae105c"
			},
			{
				"price": 1023000000,
				"size": 5234591011,
				"order_id": 0,
				"sender_id": "b7211f8a704b4815be93c07dcb354e4d"
			},
			{
				"price": 1023000000,
				"size": 1020000000,
				"order_id": 2,
				"sender_id": "fd0d457e3a4e43fe85f84d8c0b95cdd2"
			}
		],
		"asks": [
			{
				"price": 1100000000,
				"size": 80000000,
				"order_id": 3,
				"sender_id": "20a867503a244976ab894bbb54d1e76c"
			},
			{
				"price": 1100000000,
				"size": 210000000,
				"order_id": 4,
				"sender_id": "dbaae29301c24070a8237468ee52af81"
			},
			{
				"price": 1800000000,
				"size": 8056912305,
